Workbook

Sheet Guide
A1: Dataset | B1: DatasetColumn | C1: ColumnName | D1: Category_1 | E1: Category_2 | F1: Level_1_Order | G1: Level_1 | H1: Level_2 | I1: Series_1 | J1: Series_2 | K1: Rollup | L1: Dim_Group | M1: Dim_Label | N1: Tick | O1: Prefix | P1: Style | Q1: Row | R1: Stack
A2: bond | B2: Closed Bonds | C2: Closed Bonds | D2: Change in Bonds | E2: Flow | K2: Sum | L2: n | M2: n | N2: ,d | P2: Line | Q2: =ROW(Guide[[#This Row],[Row]]) -> 2 | R2: {=_xlfn.XLOOKUP( Guide[[#This Row],[Dataset]]&Guide[[#This Row],[Category_1]]&Guide[[#This Row],[Category_2]]&Guide[[#This Row],[Dim_Group]],_xlfn.ANCHORARRAY( Sheet1!$N$2),_xlfn.CHOOSECOLS(_xlfn.ANCHORARRAY(Sheet1!$I$2),5),0)} -> 2
A3: bond | B3: Lodged Bonds | C3: Lodged Bonds | D3: Bonds | F3: 1 | I3: Lodged Bonds | K3: Sum | L3: n | M3: n | N3: ,d | P3: Line | Q3: =ROW(Guide[[#This Row],[Row]]) -> 3 | R3: {=_xlfn.XLOOKUP( Guide[[#This Row],[Dataset]]&Guide[[#This Row],[Category_1]]&Guide[[#This Row],[Category_2]]&Guide[[#This Row],[Dim_Group]],_xlfn.ANCHORARRAY( Sheet1!$N$2),_xlfn.CHOOSECOLS(_xlfn.ANCHORARRAY(Sheet1!$I$2),5),0)} -> 0
A4: bond | B4: Active Bonds | C4: Active Bonds | D4: Bonds | F4: 2 | I4: Active Bonds | K4: Sum | L4: n | M4: n | N4: ,d | P4: Line | Q4: =ROW(Guide[[#This Row],[Row]]) -> 4 | R4: {=_xlfn.XLOOKUP( Guide[[#This Row],[Dataset]]&Guide[[#This Row],[Category_1]]&Guide[[#This Row],[Category_2]]&Guide[[#This Row],[Dim_Group]],_xlfn.ANCHORARRAY( Sheet1!$N$2),_xlfn.CHOOSECOLS(_xlfn.ANCHORARRAY(Sheet1!$I$2),5),0)} -> 0
A5: bond | B5: Closed Bonds | C5: Closed Bonds | D5: Bonds | F5: 3 | I5: Closed Bonds | K5: Sum | L5: n | M5: n | N5: ,d | P5: Line | Q5: =ROW(Guide[[#This Row],[Row]]) -> 5 | R5: {=_xlfn.XLOOKUP( Guide[[#This Row],[Dataset]]&Guide[[#This Row],[Category_1]]&Guide[[#This Row],[Category_2]]&Guide[[#This Row],[Dim_Group]],_xlfn.ANCHORARRAY( Sheet1!$N$2),_xlfn.CHOOSECOLS(_xlfn.ANCHORARRAY(Sheet1!$I$2),5),0)} -> 0
A6: bond | B6: Median Rent | C6: Median Rent | D6: Rent | F6: 1 | I6: Median Rent | K6: Sum | L6: $ | M6: $ | N6: ,d | P6: Line | Q6: =ROW(Guide[[#This Row],[Row]]) -> 6 | R6: {=_xlfn.XLOOKUP( Guide[[#This Row],[Dataset]]&Guide[[#This Row],[Category_1]]&Guide[[#This Row],[Category_2]]&Guide[[#This Row],[Dim_Group]],_xlfn.ANCHORARRAY( Sheet1!$N$2),_xlfn.CHOOSECOLS(_xlfn.ANCHORARRAY(Sheet1!$I$2),5),0)} -> 0
A7: bond | B7: Geometric Mean Rent | C7: Geometric Mean Rent | D7: Rent | F7: 2 | I7: Geometric Mean Rent | K7: Sum | L7: $ | M7: $ | N7: ,d | P7: Line | Q7: =ROW(Guide[[#This Row],[Row]]) -> 7 | R7: {=_xlfn.XLOOKUP( Guide[[#This Row],[Dataset]]&Guide[[#This Row],[Category_1]]&Guide[[#This Row],[Category_2]]&Guide[[#This Row],[Dim_Group]],_xlfn.ANCHORARRAY( Sheet1!$N$2),_xlfn.CHOOSECOLS(_xlfn.ANCHORARRAY(Sheet1!$I$2),5),0)} -> 0
A8: bond | B8: Upper Quartile Rent | C8: Upper Quartile Rent | D8: Rent | F8: 3 | I8: Upper Quartile Rent | K8: Sum | L8: $ | M8: $ | N8: ,d | P8: Line | Q8: =ROW(Guide[[#This Row],[Row]]) -> 8 | R8: {=_xlfn.XLOOKUP( Guide[[#This Row],[Dataset]]&Guide[[#This Row],[Category_1]]&Guide[[#This Row],[Category_2]]&Guide[[#This Row],[Dim_Group]],_xlfn.ANCHORARRAY( Sheet1!$N$2),_xlfn.CHOOSECOLS(_xlfn.ANCHORARRAY(Sheet1!$I$2),5),0)} -> 0
A9: bond | B9: Lower Quartile Rent | C9: Lower Quartile Rent | D9: Rent | F9: 4 | I9: Lower Quartile Rent | K9: Sum | L9: $ | M9: $ | N9: ,d | P9: Line | Q9: =ROW(Guide[[#This Row],[Row]]) -> 9 | R9: {=_xlfn.XLOOKUP( Guide[[#This Row],[Dataset]]&Guide[[#This Row],[Category_1]]&Guide[[#This Row],[Category_2]]&Guide[[#This Row],[Dim_Group]],_xlfn.ANCHORARRAY( Sheet1!$N$2),_xlfn.CHOOSECOLS(_xlfn.ANCHORARRAY(Sheet1!$I$2),5),0)} -> 0
A10: bond | B10: Log Std Dev Weekly Rent | C10: Log Std Dev Weekly Rent | D10: Rent | F10: 5 | I10: Log Std Dev Weekly Rent | K10: Sum | L10: $ | M10: $ | N10: ,d | P10: Line | Q10: =ROW(Guide[[#This Row],[Row]]) -> 10 | R10: {=_xlfn.XLOOKUP( Guide[[#This Row],[Dataset]]&Guide[[#This Row],[Category_1]]&Guide[[#This Row],[Category_2]]&Guide[[#This Row],[Dim_Group]],_xlfn.ANCHORARRAY( Sheet1!$N$2),_xlfn.CHOOSECOLS(_xlfn.ANCHORARRAY(Sheet1!$I$2),5),0)} -> 0
A11: hb1 | B11: EXRT.DS41.NZB17 | C11: 17 currency basket | D11: Index | E11: TWI | F11: 1 | G11: 17 currency basket | H11: Index | I11: 17 currency basket | K11: Sum | L11: TWI | M11: Index | N11: .0f | P11: Line | Q11: =ROW(Guide[[#This Row],[Row]]) -> 11 | R11: {=_xlfn.XLOOKUP( Guide[[#This Row],[Dataset]]&Guide[[#This Row],[Category_1]]&Guide[[#This Row],[Category_2]]&Guide[[#This Row],[Dim_Group]],_xlfn.ANCHORARRAY( Sheet1!$N$2),_xlfn.CHOOSECOLS(_xlfn.ANCHORARRAY(Sheet1!$I$2),5),0)} -> 11
A12: hb1 | B12: EXR.DS11.D06 | C12: United States dollar | D12: NZD/USD | E12: Exchange rates (quoted per NZ$) | F12: 1 | G12: United States dollar | H12: NZD/USD | I12: United States dollar | K12: Sum | L12: NZD to $USD | M12: NZD/USD | N12: .2f | O12: $ | P12: Line | Q12: =ROW(Guide[[#This Row],[Row]]) -> 12 | R12: {=_xlfn.XLOOKUP( Guide[[#This Row],[Dataset]]&Guide[[#This Row],[Category_1]]&Guide[[#This Row],[Category_2]]&Guide[[#This Row],[Dim_Group]],_xlfn.ANCHORARRAY( Sheet1!$N$2),_xlfn.CHOOSECOLS(_xlfn.ANCHORARRAY(Sheet1!$I$2),5),0)} -> 12
A13: hb1 | B13: EXR.DS11.D04 | C13: UK pound sterling | D13: NZD/GBP | E13: Exchange rates (quoted per NZ$) | F13: 1 | G13: UK pound sterling | H13: NZD/GBP | I13: UK pound sterling | K13: Sum | L13: NZD to Â£GBP | M13: NZD/GBP | N13: .2f | O13: Â£ | P13: Line | Q13: =ROW(Guide[[#This Row],[Row]]) -> 13 | R13: {=_xlfn.XLOOKUP( Guide[[#This Row],[Dataset]]&Guide[[#This Row],[Category_1]]&Guide[[#This Row],[Category_2]]&Guide[[#This Row],[Dim_Group]],_xlfn.ANCHORARRAY( Sheet1!$N$2),_xlfn.CHOOSECOLS(_xlfn.ANCHORARRAY(Sheet1!$I$2),5),0)} -> 13
A14: hb1 | B14: EXR.DS11.D01 | C14: Australian dollar | D14: NZD/AUD | E14: Exchange rates (quoted per NZ$) | F14: 1 | G14: Australian dollar | H14: NZD/AUD | I14: Australian dollar | K14: Sum | L14: NZD to $AUD | M14: NZD/AUD | N14: .2f | O14: $ | P14: Line | Q14: =ROW(Guide[[#This Row],[Row]]) -> 14 | R14: {=_xlfn.XLOOKUP( Guide[[#This Row],[Dataset]]&Guide[[#This Row],[Category_1]]&Guide[[#This Row],[Category_2]]&Guide[[#This Row],[Dim_Group]],_xlfn.ANCHORARRAY( Sheet1!$N$2),_xlfn.CHOOSECOLS(_xlfn.ANCHORARRAY(Sheet1!$I$2),5),0)} -> 14
A15: hb1 | B15: EXR.DS11.D05 | C15: Japanese yen | D15: NZD/JPY | E15: Exchange rates (quoted per NZ$) | F15: 1 | G15: Japanese yen | H15: NZD/JPY | I15: Japanese yen | K15: Sum | L15: NZD to Â¥JPY | M15: NZD/JPY | N15: .0f | O15: Â¥ | P15: Line | Q15: =ROW(Guide[[#This Row],[Row]]) -> 15 | R15: {=_xlfn.XLOOKUP( Guide[[#This Row],[Dataset]]&Guide[[#This Row],[Category_1]]&Guide[[#This Row],[Category_2]]&Guide[[#This Row],[Dim_Group]],_xlfn.ANCHORARRAY( Sheet1!$N$2),_xlfn.CHOOSECOLS(_xlfn.ANCHORARRAY(Sheet1!$I$2),5),0)} -> 15
A16: hb1 | B16: EXR.DS11.D03 | C16: European euro | D16: NZD/EUR | E16: Exchange rates (quoted per NZ$) | F16: 1 | G16: European euro | H16: NZD/EUR | I16: European euro | K16: Sum | L16: NZD to â‚¬EUR | M16: NZD/EUR | N16: .2f | O16: â‚¬ | P16: Line | Q16: =ROW(Guide[[#This Row],[Row]]) -> 16 | R16: {=_xlfn.XLOOKUP( Guide[[#This Row],[Dataset]]&Guide[[#This Row],[Category_1]]&Guide[[#This Row],[Category_2]]&Guide[[#This Row],[Dim_Group]],_xlfn.ANCHORARRAY( Sheet1!$N$2),_xlfn.CHOOSECOLS(_xlfn.ANCHORARRAY(Sheet1!$I$2),5),0)} -> 16
A17: hb1 | B17: EXR.DS11.D02 | C17: Canadian dollar | D17: NZD/CAD | E17: Exchange rates (quoted per NZ$) | F17: 1 | G17: Canadian dollar | H17: NZD/CAD | I17: Canadian dollar | K17: Sum | L17: NZD to $CAD | M17: NZD/CAD | N17: .2f | O17: $ | P17: Line | Q17: =ROW(Guide[[#This Row],[Row]]) -> 17 | R17: {=_xlfn.XLOOKUP( Guide[[#This Row],[Dataset]]&Guide[[#This Row],[Category_1]]&Guide[[#This Row],[Category_2]]&Guide[[#This Row],[Dim_Group]],_xlfn.ANCHORARRAY( Sheet1!$N$2),_xlfn.CHOOSECOLS(_xlfn.ANCHORARRAY(Sheet1!$I$2),5),0)} -> 17
A18: hb1 | B18: EXR.DS11.D12 | C18: South Korean won | D18: NZD/KRW | E18: Exchange rates (quoted per NZ$) | F18: 1 | G18: South Korean won | H18: NZD/KRW | I18: South Korean won | K18: Sum | L18: NZD to â‚©KRW | M18: NZD/KRW | N18: .0f | O18: â‚© | P18: Line | Q18: =ROW(Guide[[#This Row],[Row]]) -> 18 | R18: {=_xlfn.XLOOKUP( Guide[[#This Row],[Dataset]]&Guide[[#This Row],[Category_1]]&Guide[[#This Row],[Category_2]]&Guide[[#This Row],[Dim_Group]],_xlfn.ANCHORARRAY( Sheet1!$N$2),_xlfn.CHOOSECOLS(_xlfn.ANCHORARRAY(Sheet1!$I$2),5),0)} -> 18
A19: hb1 | B19: EXR.DS11.D11 | C19: Chinese renminbi | D19: NZD/CNY | E19: Exchange rates (quoted per NZ$) | F19: 1 | G19: Chinese renminbi | H19: NZD/CNY | I19: Chinese renminbi | K19: Sum | L19: NZD to Â¥CNY | M19: NZD/CNY | N19: .2f | O19: Â¥ | P19: Line | Q19: =ROW(Guide[[#This Row],[Row]]) -> 19 | R19: {=_xlfn.XLOOKUP( Guide[[#This Row],[Dataset]]&Guide[[#This Row],[Category_1]]&Guide[[#This Row],[Category_2]]&Guide[[#This Row],[Dim_Group]],_xlfn.ANCHORARRAY( Sheet1!$N$2),_xlfn.CHOOSECOLS(_xlfn.ANCHORARRAY(Sheet1!$I$2),5),0)} -> 19
A20: hb1 | B20: EXR.DS11.D14 | C20: Malaysian ringgit | D20: NZD/MYR | E20: Exchange rates (quoted per NZ$) | F20: 1 | G20: Malaysian ringgit | H20: NZD/MYR | I20: Malaysian ringgit | K20: Sum | L20: NZD to RM | M20: NZD/MYR | N20: .2f | O20: RM | P20: Line | Q20: =ROW(Guide[[#This Row],[Row]]) -> 20 | R20: {=_xlfn.XLOOKUP( Guide[[#This Row],[Dataset]]&Guide[[#This Row],[Category_1]]&Guide[[#This Row],[Category_2]]&Guide[[#This Row],[Dim_Group]],_xlfn.ANCHORARRAY( Sheet1!$N$2),_xlfn.CHOOSECOLS(_xlfn.ANCHORARRAY(Sheet1!$I$2),5),0)} -> 20
A21: hb1 | B21: EXR.DS11.D08 | C21: Hong Kong dollar | D21: NZD/HKD | E21: Exchange rates (quoted per NZ$) | F21: 1 | G21: Hong Kong dollar | H21: NZD/HKD | I21: Hong Kong dollar | K21: Sum | L21: NZD to $HK | M21: NZD/HKD | N21: .2f | O21: $ | P21: Line | Q21: =ROW(Guide[[#This Row],[Row]]) -> 21 | R21: {=_xlfn.XLOOKUP( Guide[[#This Row],[Dataset]]&Guide[[#This Row],[Category_1]]&Guide[[#This Row],[Category_2]]&Guide[[#This Row],[Dim_Group]],_xlfn.ANCHORARRAY( Sheet1!$N$2),_xlfn.CHOOSECOLS(_xlfn.ANCHORARRAY(Sheet1!$I$2),5),0)} -> 21
A22: hb1 | B22: EXR.DS11.D13 | C22: Indonesian rupiah | D22: NZD/IDR | E22: Exchange rates (quoted per NZ$) | F22: 1 | G22: Indonesian rupiah | H22: NZD/IDR | I22: Indonesian rupiah | K22: Sum | L22: NZD to p (IDR) | M22: NZD/IDR | N22: .0f | O22: p | P22: Line | Q22: =ROW(Guide[[#This Row],[Row]]) -> 22 | R22: {=_xlfn.XLOOKUP( Guide[[#This Row],[Dataset]]&Guide[[#This Row],[Category_1]]&Guide[[#This Row],[Category_2]]&Guide[[#This Row],[Dim_Group]],_xlfn.ANCHORARRAY( Sheet1!$N$2),_xlfn.CHOOSECOLS(_xlfn.ANCHORARRAY(Sheet1!$I$2),5),0)} -> 22
A23: hb1 | B23: EXR.DS11.D15 | C23: Thai baht | D23: NZD/THB | E23: Exchange rates (quoted per NZ$) | F23: 1 | G23: Thai baht | H23: NZD/THB | I23: Thai baht | K23: Sum | L23: NZD to B (THB) | M23: NZD/THB | N23: .0f | O23: B | P23: Line | Q23: =ROW(Guide[[#This Row],[Row]]) -> 23 | R23: {=_xlfn.XLOOKUP( Guide[[#This Row],[Dataset]]&Guide[[#This Row],[Category_1]]&Guide[[#This Row],[Category_2]]&Guide[[#This Row],[Dim_Group]],_xlfn.ANCHORARRAY( Sheet1!$N$2),_xlfn.CHOOSECOLS(_xlfn.ANCHORARRAY(Sheet1!$I$2),5),0)} -> 23
... A28: hb1 | B28: EXR.DS11.D33 | C28: Vietnamese dong | D28: NZD/VND | E28: Exchange rates (quoted per NZ$) | F28: 1 | G28: Vietnamese dong | H28: NZD/VND | I28: Vietnamese dong | K28: Sum | L28: NZD to â‚«VND | M28: NZD/VND | N28: .0f | O28: â‚« | P28: Line | Q28: =ROW(Guide[[#This Row],[Row]]) -> 28 | R28: {=_xlfn.XLOOKUP( Guide[[#This Row],[Dataset]]&Guide[[#This Row],[Category_1]]&Guide[[#This Row],[Category_2]]&Guide[[#This Row],[Dim_Group]],_xlfn.ANCHORARRAY( Sheet1!$N$2),_xlfn.CHOOSECOLS(_xlfn.ANCHORARRAY(Sheet1!$I$2),5),0)} -> 28
A29: hb1 | B29: EXRT.DS41.N | C29: Base June 1979=100 | D29: Index Historic | E29: Historical TWI | F29: 1 | G29: Base June 1979=100 | H29: Index | I29: Base June 1979=100 | K29: Sum | L29: TWI (H) | M29: Index | N29: .0f | P29: Line | Q29: =ROW(Guide[[#This Row],[Row]]) -> 29 | R29: {=_xlfn.XLOOKUP( Guide[[#This Row],[Dataset]]&Guide[[#This Row],[Category_1]]&Guide[[#This Row],[Category_2]]&Guide[[#This Row],[Dim_Group]],_xlfn.ANCHORARRAY( Sheet1!$N$2),_xlfn.CHOOSECOLS(_xlfn.ANCHORARRAY(Sheet1!$I$2),5),0)} -> 29
A30: hb2 | B30: INM.DP1.N | C30: Official Cash Rate (OCR) | D30: OCR | E30: Official Cash Rate (OCR) | F30: 1 | G30: NA | H30: %pa | I30: Official Cash Rate (OCR) | K30: Sum | L30: % | M30: %pa | N30: .1f | P30: Fill | Q30: =ROW(Guide[[#This Row],[Row]]) -> 30 | R30: {=_xlfn.XLOOKUP( Guide[[#This Row],[Dataset]]&Guide[[#This Row],[Category_1]]&Guide[[#This Row],[Category_2]]&Guide[[#This Row],[Dim_Group]],_xlfn.ANCHORARRAY( Sheet1!$N$2),_xlfn.CHOOSECOLS(_xlfn.ANCHORARRAY(Sheet1!$I$2),5),0)} -> 30
A31: hb2 | B31: INM.DG101.NZZCF | C31: 1 year (bond) | D31: Secondary market government bond closing yields | E31: 1 year | F31: 1 | G31: NA | H31: %pa | I31: 1 year (bond) | K31: Sum | L31: % | M31: %pa | N31: .1f | P31: Line | Q31: =ROW(Guide[[#This Row],[Row]]) -> 31 | R31: {=_xlfn.XLOOKUP( Guide[[#This Row],[Dataset]]&Guide[[#This Row],[Category_1]]&Guide[[#This Row],[Category_2]]&Guide[[#This Row],[Dim_Group]],_xlfn.ANCHORARRAY( Sheet1!$N$2),_xlfn.CHOOSECOLS(_xlfn.ANCHORARRAY(Sheet1!$I$2),5),0)} -> 31
A32: hb2 | B32: INM.DG102.NZZCF | C32: 2 year (bond) | D32: Secondary market government bond closing yields | E32: 2 year | F32: 1 | G32: NA | H32: %pa | I32: 2 year (bond) | K32: Sum | L32: % | M32: %pa | N32: .1f | P32: Line | Q32: =ROW(Guide[[#This Row],[Row]]) -> 32 | R32: {=_xlfn.XLOOKUP( Guide[[#This Row],[Dataset]]&Guide[[#This Row],[Category_1]]&Guide[[#This Row],[Category_2]]&Guide[[#This Row],[Dim_Group]],_xlfn.ANCHORARRAY( Sheet1!$N$2),_xlfn.CHOOSECOLS(_xlfn.ANCHORARRAY(Sheet1!$I$2),5),0)} -> 32
A33: hb2 | B33: INM.DG105.NZZCF | C33: 5 year (bond) | D33: Secondary market government bond closing yields | E33: 5 year | F33: 1 | G33: NA | H33: %pa | I33: 5 year (bond) | K33: Sum | L33: % | M33: %pa | N33: .1f | P33: Line | Q33: =ROW(Guide[[#This Row],[Row]]) -> 33 | R33: {=_xlfn.XLOOKUP( Guide[[#This Row],[Dataset]]&Guide[[#This Row],[Category_1]]&Guide[[#This Row],[Category_2]]&Guide[[#This Row],[Dim_Group]],_xlfn.ANCHORARRAY( Sheet1!$N$2),_xlfn.CHOOSECOLS(_xlfn.ANCHORARRAY(Sheet1!$I$2),5),0)} -> 33
A34: hb2 | B34: INM.DG110.NZZCF | C34: 10 year (bond) | D34: Secondary market government bond closing yields | E34: 10 year | F34: 1 | G34: NA | H34: %pa | I34: 10 year (bond) | K34: Sum | L34: % | M34: %pa | N34: .1f | P34: Line | Q34: =ROW(Guide[[#This Row],[Row]]) -> 34 | R34: {=_xlfn.XLOOKUP( Guide[[#This Row],[Dataset]]&Guide[[#This Row],[Category_1]]&Guide[[#This Row],[Category_2]]&Guide[[#This Row],[Dim_Group]],_xlfn.ANCHORARRAY( Sheet1!$N$2),_xlfn.CHOOSECOLS(_xlfn.ANCHORARRAY(Sheet1!$I$2),5),0)} -> 34
A35: hb2 | B35: INM.DS01.NZZC | C35: 1 year (swap) | D35: Swap rates close | E35: 1 year | F35: 1 | G35: NA | H35: %pa | I35: 1 year (swap) | K35: Sum | L35: % | M35: %pa | N35: .1f | P35: Line | Q35: =ROW(Guide[[#This Row],[Row]]) -> 35 | R35: {=_xlfn.XLOOKUP( Guide[[#This Row],[Dataset]]&Guide[[#This Row],[Category_1]]&Guide[[#This Row],[Category_2]]&Guide[[#This Row],[Dim_Group]],_xlfn.ANCHORARRAY( Sheet1!$N$2),_xlfn.CHOOSECOLS(_xlfn.ANCHORARRAY(Sheet1!$I$2),5),0)} -> 35
A36: hb2 | B36: INM.DS02.NZZC | C36: 2 year (swap) | D36: Swap rates close | E36: 2 year | F36: 1 | G36: NA | H36: %pa | I36: 2 year (swap) | K36: Sum | L36: % | M36: %pa | N36: .1f | P36: Line | Q36: =ROW(Guide[[#This Row],[Row]]) -> 36 | R36: {=_xlfn.XLOOKUP( Guide[[#This Row],[Dataset]]&Guide[[#This Row],[Category_1]]&Guide[[#This Row],[Category_2]]&Guide[[#This Row],[Dim_Group]],_xlfn.ANCHORARRAY( Sheet1!$N$2),_xlfn.CHOOSECOLS(_xlfn.ANCHORARRAY(Sheet1!$I$2),5),0)} -> 36
A37: hb2 | B37: INM.DS05.NZZC | C37: 5 year (swap) | D37: Swap rates close | E37: 5 year | F37: 1 | G37: NA | H37: %pa | I37: 5 year (swap) | K37: Sum | L37: % | M37: %pa | N37: .1f | P37: Line | Q37: =ROW(Guide[[#This Row],[Row]]) -> 37 | R37: {=_xlfn.XLOOKUP( Guide[[#This Row],[Dataset]]&Guide[[#This Row],[Category_1]]&Guide[[#This Row],[Category_2]]&Guide[[#This Row],[Dim_Group]],_xlfn.ANCHORARRAY( Sheet1!$N$2),_xlfn.CHOOSECOLS(_xlfn.ANCHORARRAY(Sheet1!$I$2),5),0)} -> 37
A38: hb2 | B38: INM.DS10.NZZC | C38: 10 year (swap) | D38: Swap rates close | E38: 10 year | F38: 1 | G38: NA | H38: %pa | I38: 10 year (swap) | K38: Sum | L38: % | M38: %pa | N38: .1f | P38: Line | Q38: =ROW(Guide[[#This Row],[Row]]) -> 38 | R38: {=_xlfn.XLOOKUP( Guide[[#This Row],[Dataset]]&Guide[[#This Row],[Category_1]]&Guide[[#This Row],[Category_2]]&Guide[[#This Row],[Dim_Group]],_xlfn.ANCHORARRAY( Sheet1!$N$2),_xlfn.CHOOSECOLS(_xlfn.ANCHORARRAY(Sheet1!$I$2),5),0)} -> 38
A39: hb2 | B39: INM.DS61.NZZC | C39: Spread 2-10 year | D39: Swap rates close | E39: Spread 2-10 year | F39: 1 | G39: NA | H39: bps | I39: Spread 2-10 year | K39: Sum | L39: bps | M39: bps | N39: .1f | P39: Line | Q39: =ROW(Guide[[#This Row],[Row]]) -> 39 | R39: {=_xlfn.XLOOKUP( Guide[[#This Row],[Dataset]]&Guide[[#This Row],[Category_1]]&Guide[[#This Row],[Category_2]]&Guide[[#This Row],[Dim_Group]],_xlfn.ANCHORARRAY( Sheet1!$N$2),_xlfn.CHOOSECOLS(_xlfn.ANCHORARRAY(Sheet1!$I$2),5),0)} -> 39
A40: hc35 | B40: LVRP.QME1.A | C40: Opening position | D40: Total | E40: Opening position | F40: 1 | G40: Total | H40: NZDm | I40: Opening position | K40: Sum | L40: NZDm | M40: NZDm | N40: ,d | P40: Fill | Q40: =ROW(Guide[[#This Row],[Row]]) -> 40 | R40: {=_xlfn.XLOOKUP( Guide[[#This Row],[Dataset]]&Guide[[#This Row],[Category_1]]&Guide[[#This Row],[Category_2]]&Guide[[#This Row],[Dim_Group]],_xlfn.ANCHORARRAY( Sheet1!$N$2),_xlfn.CHOOSECOLS(_xlfn.ANCHORARRAY(Sheet1!$I$2),5),0)} -> 40
... A389: bond | B389: Log Std Dev Weekly Rent | C389: Log Std Dev Weekly Rent | D389: NA | E389: NA | F389: 8 | G389: NA | H389: NA | I389: Log Std Dev Weekly Rent | K389: Sum | L389: $ | M389: NA | N389: ,d | P389: Line | Q389: =ROW(Guide[[#This Row],[Row]]) -> 389 | R389: {=_xlfn.XLOOKUP( Guide[[#This Row],[Dataset]]&Guide[[#This Row],[Category_1]]&Guide[[#This Row],[Category_2]]&Guide[[#This Row],[Dim_Group]],_xlfn.ANCHORARRAY( Sheet1!$N$2),_xlfn.CHOOSECOLS(_xlfn.ANCHORARRAY(Sheet1!$I$2),5),0)} -> 389
A390: border | B390: Arrivals | C390: Arrivals | D390: - | E390: - | F390: 1 | G390: - | H390: - | I390: Arrivals | K390: Sum | L390: - | M390: - | N390: ,d | Q390: =ROW(Guide[[#This Row],[Row]]) -> 390 | R390: {=_xlfn.XLOOKUP( Guide[[#This Row],[Dataset]]&Guide[[#This Row],[Category_1]]&Guide[[#This Row],[Category_2]]&Guide[[#This Row],[Dim_Group]],_xlfn.ANCHORARRAY( Sheet1!$N$2),_xlfn.CHOOSECOLS(_xlfn.ANCHORARRAY(Sheet1!$I$2),5),0)} -> 390
A391: NDM01 | B391: All house types | C391: VALUE | D391: All house types | E391: All house types | F391: 1 | G391: Total | H391: - | I391: VALUE | K391: Sum | L391: - | M391: - | N391: ,d | P391: Fill | Q391: =ROW(Guide[[#This Row],[Row]]) -> 391 | R391: {=_xlfn.XLOOKUP( Guide[[#This Row],[Dataset]]&Guide[[#This Row],[Category_1]]&Guide[[#This Row],[Category_2]]&Guide[[#This Row],[Dim_Group]],_xlfn.ANCHORARRAY( Sheet1!$N$2),_xlfn.CHOOSECOLS(_xlfn.ANCHORARRAY(Sheet1!$I$2),5),0)} -> 391
A392: NDM01 | B392: Single house | C392: VALUE | D392: Single house | E392: Single house | F392: 1 | G392: Stack | H392: - | I392: VALUE | K392: Sum | L392: - | M392: - | N392: ,d | P392: Line | Q392: =ROW(Guide[[#This Row],[Row]]) -> 392 | R392: {=_xlfn.XLOOKUP( Guide[[#This Row],[Dataset]]&Guide[[#This Row],[Category_1]]&Guide[[#This Row],[Category_2]]&Guide[[#This Row],[Dim_Group]],_xlfn.ANCHORARRAY( Sheet1!$N$2),_xlfn.CHOOSECOLS(_xlfn.ANCHORARRAY(Sheet1!$I$2),5),0)} -> 392
...

Sheet Sheet1
A2: {=_xlfn.PIVOTBY(_xlfn.HSTACK( Guide[Dataset],Guide[Category_1],Guide[Category_2],Guide[Level_1_Order],Guide[Level_2],Guide[Dim_Group] ),,Guide[Row],_xleta.MAX)} -> adp | B2: NA | C2: NA | D2: 1 | E2: NA | F2: NA | G2: 364 | I2: {=_xlfn.PIVOTBY(_xlfn.HSTACK( Guide[Dataset],Guide[Category_1],Guide[Category_2],Guide[Dim_Group] ),,Guide[Row],_xleta.MAX)} -> adp | J2: NA | K2: NA | L2: NA | M2: 381 | N2: {=_xlfn.CHOOSECOLS(_xlfn.ANCHORARRAY(I2),1)&_xlfn.CHOOSECOLS(_xlfn.ANCHORARRAY(I2),2)&_xlfn.CHOOSECOLS(_xlfn.ANCHORARRAY(I2),3)&_xlfn.CHOOSECOLS(_xlfn.ANCHORARRAY(I2),4)} -> adpNANANA
A3: adp | B3: NA | C3: NA | D3: 2 | E3: NA | F3: NA | G3: 365 | I3: bond | J3: Bonds | K3: 0 | L3: n | M3: 5 | N3: bondBonds0n
A4: adp | B4: NA | C4: NA | D4: 3 | E4: NA | F4: NA | G4: 366 | I4: bond | J4: Change in Bonds | K4: Flow | L4: n | M4: 2 | N4: bondChange in BondsFlown
A5: adp | B5: NA | C5: NA | D5: 4 | E5: NA | F5: NA | G5: 367 | I5: bond | J5: NA | K5: NA | L5: $ | M5: 389 | N5: bondNANA$
A6: adp | B6: NA | C6: NA | D6: 5 | E6: NA | F6: NA | G6: 368 | I6: bond | J6: Rent | K6: 0 | L6: $ | M6: 10 | N6: bondRent0$
A7: adp | B7: NA | C7: NA | D7: 6 | E7: NA | F7: NA | G7: 369 | I7: border | J7: - | K7: - | L7: - | M7: 390 | N7: border---
A8: adp | B8: NA | C8: NA | D8: 7 | E8: NA | F8: NA | G8: 370 | I8: fuel | J8: NA | K8: NZD per Barrel | L8: $ | M8: 363 | N8: fuelNANZD per Barrel$
A9: adp | B9: NA | C9: NA | D9: 8 | E9: NA | F9: NA | G9: 371 | I9: fuel | J9: NA | K9: USD per Barrel | L9: $ | M9: 362 | N9: fuelNAUSD per Barrel$
A10: adp | B10: NA | C10: NA | D10: 9 | E10: NA | F10: NA | G10: 372 | I10: hb1 | J10: Index | K10: TWI | L10: TWI | M10: 11 | N10: hb1IndexTWITWI
A11: adp | B11: NA | C11: NA | D11: 10 | E11: NA | F11: NA | G11: 373 | I11: hb1 | J11: Index Historic | K11: Historical TWI | L11: TWI (H) | M11: 29 | N11: hb1Index HistoricHistorical TWITWI (H)
A12: adp | B12: NA | C12: NA | D12: 11 | E12: NA | F12: NA | G12: 374 | I12: hb1 | J12: NZD/AUD | K12: Exchange rates (quoted per NZ$) | L12: NZD to $AUD | M12: 14 | N12: hb1NZD/AUDExchange rates (quoted per NZ$)NZD to $AUD
A13: adp | B13: NA | C13: NA | D13: 12 | E13: NA | F13: NA | G13: 375 | I13: hb1 | J13: NZD/CAD | K13: Exchange rates (quoted per NZ$) | L13: NZD to $CAD | M13: 17 | N13: hb1NZD/CADExchange rates (quoted per NZ$)NZD to $CAD
A14: adp | B14: NA | C14: NA | D14: 13 | E14: NA | F14: NA | G14: 376 | I14: hb1 | J14: NZD/CNY | K14: Exchange rates (quoted per NZ$) | L14: NZD to Â¥CNY | M14: 19 | N14: hb1NZD/CNYExchange rates (quoted per NZ$)NZD to Â¥CNY
A15: adp | B15: NA | C15: NA | D15: 14 | E15: NA | F15: NA | G15: 377 | I15: hb1 | J15: NZD/EUR | K15: Exchange rates (quoted per NZ$) | L15: NZD to â‚¬EUR | M15: 16 | N15: hb1NZD/EURExchange rates (quoted per NZ$)NZD to â‚¬EUR
A16: adp | B16: NA | C16: NA | D16: 15 | E16: NA | F16: NA | G16: 378 | I16: hb1 | J16: NZD/GBP | K16: Exchange rates (quoted per NZ$) | L16: NZD to Â£GBP | M16: 13 | N16: hb1NZD/GBPExchange rates (quoted per NZ$)NZD to Â£GBP
A17: adp | B17: NA | C17: NA | D17: 16 | E17: NA | F17: NA | G17: 379 | I17: hb1 | J17: NZD/HKD | K17: Exchange rates (quoted per NZ$) | L17: NZD to $HK | M17: 21 | N17: hb1NZD/HKDExchange rates (quoted per NZ$)NZD to $HK
A18: adp | B18: NA | C18: NA | D18: 17 | E18: NA | F18: NA | G18: 380 | I18: hb1 | J18: NZD/IDR | K18: Exchange rates (quoted per NZ$) | L18: NZD to p (IDR) | M18: 22 | N18: hb1NZD/IDRExchange rates (quoted per NZ$)NZD to p (IDR)
A19: adp | B19: NA | C19: NA | D19: 18 | E19: NA | F19: NA | G19: 381 | I19: hb1 | J19: NZD/INR | K19: Exchange rates (quoted per NZ$) | L19: NZD to â‚¹INR | M19: 26 | N19: hb1NZD/INRExchange rates (quoted per NZ$)NZD to â‚¹INR
A20: bond | B20: Bonds | C20: 0 | D20: 1 | E20: 0 | F20: n | G20: 3 | I20: hb1 | J20: NZD/JPY | K20: Exchange rates (quoted per NZ$) | L20: NZD to Â¥JPY | M20: 15 | N20: hb1NZD/JPYExchange rates (quoted per NZ$)NZD to Â¥JPY
A21: bond | B21: Bonds | C21: 0 | D21: 2 | E21: 0 | F21: n | G21: 4 | I21: hb1 | J21: NZD/KRW | K21: Exchange rates (quoted per NZ$) | L21: NZD to â‚©KRW | M21: 18 | N21: hb1NZD/KRWExchange rates (quoted per NZ$)NZD to â‚©KRW
A22: bond | B22: Bonds | C22: 0 | D22: 3 | E22: 0 | F22: n | G22: 5 | I22: hb1 | J22: NZD/MYR | K22: Exchange rates (quoted per NZ$) | L22: NZD to RM | M22: 20 | N22: hb1NZD/MYRExchange rates (quoted per NZ$)NZD to RM
A23: bond | B23: Change in Bonds | C23: Flow | D23: 0 | E23: 0 | F23: n | G23: 2 | I23: hb1 | J23: NZD/PHP | K23: Exchange rates (quoted per NZ$) | L23: NZD to â‚±PHP | M23: 27 | N23: hb1NZD/PHPExchange rates (quoted per NZ$)NZD to â‚±PHP
A24: bond | B24: NA | C24: NA | D24: 1 | E24: NA | F24: $ | G24: 382 | I24: hb1 | J24: NZD/SGD | K24: Exchange rates (quoted per NZ$) | L24: NZD to $SGD | M24: 24 | N24: hb1NZD/SGDExchange rates (quoted per NZ$)NZD to $SGD
A25: bond | B25: NA | C25: NA | D25: 2 | E25: NA | F25: $ | G25: 383 | I25: hb1 | J25: NZD/THB | K25: Exchange rates (quoted per NZ$) | L25: NZD to B (THB) | M25: 23 | N25: hb1NZD/THBExchange rates (quoted per NZ$)NZD to B (THB)
A26: bond | B26: NA | C26: NA | D26: 3 | E26: NA | F26: $ | G26: 384 | I26: hb1 | J26: NZD/TWD | K26: Exchange rates (quoted per NZ$) | L26: NZD to $NT | M26: 25 | N26: hb1NZD/TWDExchange rates (quoted per NZ$)NZD to $NT
A27: bond | B27: NA | C27: NA | D27: 4 | E27: NA | F27: $ | G27: 385 | I27: hb1 | J27: NZD/USD | K27: Exchange rates (quoted per NZ$) | L27: NZD to $USD | M27: 12 | N27: hb1NZD/USDExchange rates (quoted per NZ$)NZD to $USD
A28: bond | B28: NA | C28: NA | D28: 5 | E28: NA | F28: $ | G28: 386 | I28: hb1 | J28: NZD/VND | K28: Exchange rates (quoted per NZ$) | L28: NZD to â‚«VND | M28: 28 | N28: hb1NZD/VNDExchange rates (quoted per NZ$)NZD to â‚«VND
A29: bond | B29: NA | C29: NA | D29: 6 | E29: NA | F29: $ | G29: 387 | I29: hb2 | J29: OCR | K29: Official Cash Rate (OCR) | L29: % | M29: 30 | N29: hb2OCROfficial Cash Rate (OCR)%
A30: bond | B30: NA | C30: NA | D30: 7 | E30: NA | F30: $ | G30: 388 | I30: hb2 | J30: Secondary market government bond closing yields | K30: 1 year | L30: % | M30: 31 | N30: hb2Secondary market government bond closing yields1 year%
A31: bond | B31: NA | C31: NA | D31: 8 | E31: NA | F31: $ | G31: 389 | I31: hb2 | J31: Secondary market government bond closing yields | K31: 10 year | L31: % | M31: 34 | N31: hb2Secondary market government bond closing yields10 year%
A32: bond | B32: Rent | C32: 0 | D32: 1 | E32: 0 | F32: $ | G32: 6 | I32: hb2 | J32: Secondary market government bond closing yields | K32: 2 year | L32: % | M32: 32 | N32: hb2Secondary market government bond closing yields2 year%
A33: bond | B33: Rent | C33: 0 | D33: 2 | E33: 0 | F33: $ | G33: 7 | I33: hb2 | J33: Secondary market government bond closing yields | K33: 5 year | L33: % | M33: 33 | N33: hb2Secondary market government bond closing yields5 year%
A34: bond | B34: Rent | C34: 0 | D34: 3 | E34: 0 | F34: $ | G34: 8 | I34: hb2 | J34: Swap rates close | K34: 1 year | L34: % | M34: 35 | N34: hb2Swap rates close1 year%
A35: bond | B35: Rent | C35: 0 | D35: 4 | E35: 0 | F35: $ | G35: 9 | I35: hb2 | J35: Swap rates close | K35: 10 year | L35: % | M35: 38 | N35: hb2Swap rates close10 year%
A36: bond | B36: Rent | C36: 0 | D36: 5 | E36: 0 | F36: $ | G36: 10 | I36: hb2 | J36: Swap rates close | K36: 2 year | L36: % | M36: 36 | N36: hb2Swap rates close2 year%
A37: border | B37: - | C37: - | D37: 1 | E37: - | F37: - | G37: 390 | I37: hb2 | J37: Swap rates close | K37: 5 year | L37: % | M37: 37 | N37: hb2Swap rates close5 year%
A38: fuel | B38: NA | C38: NZD per Barrel | D38: 1 | E38: NA | F38: $ | G38: 363 | I38: hb2 | J38: Swap rates close | K38: Spread 2-10 year | L38: bps | M38: 39 | N38: hb2Swap rates closeSpread 2-10 yearbps
A39: fuel | B39: NA | C39: USD per Barrel | D39: 1 | E39: NA | F39: $ | G39: 362 | I39: hc35 | J39: <=80% LVR | K39: Drawdowns | L39: NZDm | M39: 59 | N39: hc35<=80% LVRDrawdownsNZDm
A40: hb1 | B40: Index | C40: TWI | D40: 1 | E40: Index | F40: TWI | G40: 11 | I40: hc35 | J40: <=80% LVR | K40: Interest charged | L40: NZDm | M40: 60 | N40: hc35<=80% LVRInterest chargedNZDm
A41: hb1 | B41: Index Historic | C41: Historical TWI | D41: 1 | E41: Index | F41: TWI (H) | G41: 29 | I41: hc35 | J41: <=80% LVR | K41: Net write-offs | L41: NZDm | M41: 65 | N41: hc35<=80% LVRNet write-offsNZDm
...
